const catchAsync = fun => {
  return async (req, res, next) => {
    try {
      await fun(req, res, next);
    } catch (err) {
      console.log(err);
      next(err);
    }
  };
};

export default catchAsync;
